<?xml version="1.0"?>
<robot name="visual">
    <link name="base_link">
        <visual>
            <geometry>
                <cylinder length="0.01" radius="0.047" />
            </geometry>
            <material name="black" />
            <origin rpy="0 0 0" xyz="0 0 0" />
        </visual>
    </link>
    <link name="arm_base_link">
        <visual>
            <geometry>
                <mesh filename="package://eezybotarm/meshes/eezybotarm_base.stl" scale="0.001 0.001 0.001" />
            </geometry>
            <material name="orange" />
            <origin rpy="0 0 3.1416" xyz="0 0.0055 0" />
        </visual>
    </link>
    <link name="arm_rotate_base_link">
        <visual>
            <geometry>
                <mesh filename="package://eezybotarm/meshes/eezybotarm_rotate_base.stl" scale="0.001 0.001 0.001" />
            </geometry>
            <material name="orange" />
            <origin rpy="0 0 0" xyz="0.0015 0.013 0" />
        </visual>
    </link>

    <link name="arm_forward_drive_link">
        <visual>
            <geometry>
                <mesh filename="package://eezybotarm/meshes/eezybotarm_forward_drive.stl" scale="0.001 0.001 0.001" />
            </geometry>
            <material name="orange" />
            <origin rpy="0 0 0" xyz="0 0 0" />
        </visual>
    </link>

    <link name="arm_vertical_drive_link">
        <visual>
            <geometry>
                <mesh filename="package://eezybotarm/meshes/eezybotarm_vertical_drive.stl" scale="0.001 0.001 0.001" />
            </geometry>
            <material name="orange" />
            <origin rpy="0 0 0" xyz="0 0 0" />
        </visual>
    </link>

    <joint name="base_joint" type="fixed">
        <axis xyz="0 0 -1" />
        <limit effort="1000.0" lower="0.0" upper="3.1416" velocity="1.0" />
        <origin rpy="0 0 0" xyz="0 0 0" />
        <parent link="base_link" />
        <child link="arm_base_link" />
    </joint>

    <joint name="rotate_base_joint" type="revolute">
        <axis xyz="0 0 1" />
        <limit effort="1000.0" lower="0.0" upper="3.1416" velocity="1.0" />
        <origin rpy="0 0 0" xyz="0.000 0 0.032" />
        <parent link="arm_base_link" />
        <child link="arm_rotate_base_link" />
    </joint>

    <joint name="forward_drive_joint" type="revolute">
        <axis xyz="1 0 0" />
        <limit effort="1000.0" lower="0" upper="3.1416" velocity="1.0" />
        <origin rpy="-1.5708 -1.5708 3.14159" xyz="0.0015 -0.005 0.074" />
        <parent link="arm_rotate_base_link" />
        <child link="arm_forward_drive_link" />
    </joint>

    <joint name="vertical_drive_joint" type="revolute">
        <axis xyz="1 0 0" />
        <limit effort="1000.0" lower="0" upper="3.1416" velocity="1.0" />
        <origin rpy="1.5708 1.5708 -1.5708" xyz="-0.0135 -0.012 0.052" />
        <parent link="arm_rotate_base_link" />
        <child link="arm_vertical_drive_link" />
    </joint>

    <material name="orange">
        <color rgba="0.57 0.17 0.0 1" />
    </material>
    <material name="white">
        <color rgba="0.8 0.8 0.8 1.0" />
    </material>
    <material name="black">
        <color rgba="0 0 0 0.50" />
    </material>
</robot>